Traceback (most recent call last):
  File "/home/gopi/.local/lib/python3.10/site-packages/jupyter_cache/executors/utils.py", line 58, in single_nb_execution
    executenb(
  File "/usr/lib/python3/dist-packages/nbclient/client.py", line 1093, in execute
    return NotebookClient(nb=nb, resources=resources, km=km, **kwargs).execute()
  File "/usr/lib/python3/dist-packages/nbclient/util.py", line 84, in wrapped
    return just_run(coro(*args, **kwargs))
  File "/usr/lib/python3/dist-packages/nbclient/util.py", line 62, in just_run
    return loop.run_until_complete(coro)
  File "/usr/lib/python3.10/asyncio/base_events.py", line 649, in run_until_complete
    return future.result()
  File "/usr/lib/python3/dist-packages/nbclient/client.py", line 559, in async_execute
    await self.async_execute_cell(
  File "/usr/lib/python3/dist-packages/nbclient/client.py", line 854, in async_execute_cell
    self._check_raise_for_error(cell, exec_reply)
  File "/usr/lib/python3/dist-packages/nbclient/client.py", line 756, in _check_raise_for_error
    raise CellExecutionError.from_cell_and_msg(cell, exec_reply_content)
nbclient.exceptions.CellExecutionError: An error occurred while executing the following cell:
------------------
from accelerate import Accelerator
from transformers import AdamW, get_scheduler
from tqdm import tqdm

accelerator = Accelerator()

optimizer = AdamW(model.parameters(), lr=3e-5)



num_epochs = 1

lr_scheduler = get_scheduler(
  "linear",
  optimizer=optimizer,
  num_warmup_steps=0,
  num_training_steps=num_training_steps
)

train_dataloader, eval_dataloader, model, optimizer, scheduler = accelerator.prepare(
     train_loader, valid_loader, model, optimizer, lr_scheduler
 )
num_training_steps = num_epochs * len(train_dataloader)

progress_bar = tqdm(range(num_training_steps))

loss_fn = LLMLoss()



model.train()
for epoch in range(num_epochs):
    for batch in train_dataloader:
        features,target = batch
        logits = model(features)
        loss = loss_fn(logits, target)
        accelerator.backward(loss)
        optimizer.step()
        scheduler.step()
        progress_bar.update(1)
      

------------------

[0;31m---------------------------------------------------------------------------[0m
[0;31mNameError[0m                                 Traceback (most recent call last)
[0;32m/tmp/ipykernel_92767/2352630947.py[0m in [0;36m<module>[0;34m[0m
[1;32m     15[0m   [0moptimizer[0m[0;34m=[0m[0moptimizer[0m[0;34m,[0m[0;34m[0m[0;34m[0m[0m
[1;32m     16[0m   [0mnum_warmup_steps[0m[0;34m=[0m[0;36m0[0m[0;34m,[0m[0;34m[0m[0;34m[0m[0m
[0;32m---> 17[0;31m   [0mnum_training_steps[0m[0;34m=[0m[0mnum_training_steps[0m[0;34m[0m[0;34m[0m[0m
[0m[1;32m     18[0m )
[1;32m     19[0m [0;34m[0m[0m

[0;31mNameError[0m: name 'num_training_steps' is not defined
NameError: name 'num_training_steps' is not defined

